Traceback (most recent call last):
  File "writeErrorInfo.py", line 4, in <module>
    raise Exception('これはエラーメッセージです。')
Exception: これはエラーメッセージです。
